Workbook

Sheet Website Performance Analysis
A1: Project | Analyzing Website Performance for The Grammys
A3: • All of your answers should be typed or pasted into the grey boxes. • Questions with grey answer boxes expect a specific answer. Once you input the correct answer, the question number box will change from blue to green. • Questions with yellow answer boxes are free-response questions. There will be no change in the question number boxes (in blue), regardless of your answer. • Hover your cursor over the blue hint box to get a helpful hint!
A14: Part 1: Exploring the Data
A16: The Grammys Data sheet contains two tables: the web analytics data for Grammy.com (Grammys) and a second table for mobile visitors on the site (mobile_visits). The Recording Academy Data sheet contains the web analytics for recordingacademy.com after they split the websites. To begin the data exploration you will be looking at The Grammys Data sheet.
A22: 1a | B22: Use the Grammys datatable to creata a line chart of the number of daily visitors to the Grammy.com website. The horizontal axis should be the date field. | D22: Hint!
A40: 1b | B40: What do you notice about when and why traffic spikes occur? Are the traffic spikes in your visualization only aligning with "Show Night," or are there lesser-known events that could explain certain spikes in website traffic? | D40: Hint!
A42: The chart shows clear annual traffic spikes between 2017 and 2023 that align with major Grammy events. The largest spike each year corresponds to the Grammy Awards ceremony (“Show Night”), which typically occurs between late January and early February, except in 2021 and 2022 when the event was delayed to March and April due to COVID-19. Smaller spikes occurring toward the end of each year are likely associated with nomination announcements and performer reveals. The highest traffic occurs in 2021 with approximately 3.3 million visitors, followed by significant peaks in 2019 and 2023. This indicates that website traffic is highly event-driven and concentrated around key Grammy milestones rather than evenly distributed throughout the year.
A46: Try this prompt: Can you identify any specific lesser-known events (with exact dates) that might have caused significant increases in website traffic on grammys.com? What external data sources could help confirm these trends?
A49: 2a | B49: Using the Grammys Data sheet, create a PivotTable to compare the average daily website visitors on days when an award ceremony was held to those when no awards ceremonies were held. | D49: Hint!
A51: 2b | B51: What does this comparison reveal about the difference in traffic between award ceremony days and regular days? How many more visitors does the Grammy Awards site receive on Show Night?
A53: The table shows a significant increase in the average number of visitors during the award ceremony compared to the regular days. During the award show, the average number of visitors was close to 1.4 million, whereas on regular days it was just around 32000, which is about 2% of the total average visitors during the award show. This does not significantly make differences to the visitors for the award show since it still remains in the figure of 1.25 to 1.4 million. The exact number of additional visitors during the award shows was 1,357,201.95406 on average.
A56: 3 | B56: February 1st, 2022 marks the transition from when Grammy.com began to only host Grammys content instead of both Recording Academy and Grammys content. Fill in the values in the website_content column in The Grammys Data sheet. This column will have the value "Grammys" if the date occurred on or after 2/1/2022 and the value "Grammys + TRA" otherwise. | D56: Hint!
A60: Part 2: Analyzing Key Metrics
A62: Remember the overall goal of this project: to analze whether splitting the website into two has improved user engagement. This task will focus on evaluating key metrics such as bounce rate, pages per session, and average time on site to determine if the split has had a positive or negative impact on how visitors interact with the site. You'll calculate the pages_per_session metric by first finding the total pageviews. Then you'll divide that total by the total number of sessions. Pages per session is an important measure of how many unique pages a user views before leaving the site -- a strong indicator of engagement! | G62: website_content | H62: Sum of pageviews | I62: Sum of sessions
G63: Grammys | H63: 54576120 | I63: 24220888
G64: Grammys TRA | H64: 149619377 | I64: 80414221
G65: Grand Total | H65: 204195497 | I65: 104635109
A68: 4a | B68: What is the pages_per_session on the Recording Academy data? | C68: =(SUM('Recording Academy Data'!D:D)/SUM('Recording Academy Data'!E:E)) -> 2.7792846 | D68: Hint!
A69: 4b | B69: What is the pages_per_session on the Grammys data? | C69: =H63/I63 -> 2.2532667
A70: 4c | B70: What is the pages_per_session on the Grammys + TRA data? | C70: =H64/I64 -> 1.8606084
A71: 4d | B71: In one sentence, what does this metric suggest regarding the impact of the website split?
A72: Try this prompt: What does pages per session reveal about user engagement? How should I interpret changes in this metric after the website split?
A74: The pages per session metric indicates that user engagement is higher on the Recording Academy site than on the Grammys site, suggesting that the website split allowed each audience to access more relevant content, with Recording Academy visitors exploring more pages while Grammys users exhibit shorter, event-driven sessions.
A76: You'll calculate the bounce_rate metric by first calculating the total bounced_sessions and dividing that by the total number of sessions. Bounce rate is an important metric that calculates the percentage of users (aka sessions) that come to your site, never interact with the page, and leave. They are said to have "bounced" off your home page. It is a measure of how engaging your home page is with users.
A79: 5a | B79: What is the bounce_rate on the Recording Academy data? | C79: =(SUM(TRA[bounced_sessions])/SUM('Recording Academy Data'!E:E)) -> 0.33671924 | D79: Hint!
A80: 5b | B80: What is the bounce_rate on the Grammys data? | C80: =(SUMIFS(Grammys[bounced_sessions],Grammys[website_content],"Grammys")/SUMIFS(Grammys[sessions],Grammys[website_content],"Grammys"))*100 -> 40.158614
A81: 5c | B81: What is the bounce_rate on the Grammys + TRA data? | C81: =(SUMIFS(Grammys[bounced_sessions],Grammys[website_content],"Grammys TRA")/SUMIFS(Grammys[sessions],Grammys[website_content],"Grammys TRA")) -> 0.41584428
A82: Next, you'll calculate the average_time_on_site metric.To do this, you only need to calculate the average of the avg_session_duration_secs column. Average Time on Site measures how engaging your website experience is for your users. The higher the number, the longer they are staying on your page and engaging with the content.
A85: 6a | B85: What is the average_time_on_site on the Recording Academy data? | C85: =AVERAGE(TRA[avg_session_duration_secs]) -> 128.50309 | D85: Hint!
A86: 6b | B86: What is the average_time_on_site on the Grammys data? | C86: =AVERAGEIFS(Grammys[avg_session_duration_secs],Grammys[website_content],"Grammys") -> 82.985567
A87: 6c | B87: What is the average_time_on_site on the Grammys + TRA data? | C87: =AVERAGEIFS(Grammys[avg_session_duration_secs],Grammys[website_content],"Grammys TRA") -> 102.85353
A88: 6d | B88: Which of these three metrics changed the most after the site split? What do these changes suggest about user behavior?
A89: After the site split, average time on site increased significantly for the Recording Academy (128.50 seconds) compared to the combined site (102.85 seconds), while the Grammys site decreased to 82.99 seconds. This suggests that users who visit the Recording Academy site are more engaged and spend more time consuming content, whereas Grammys visitors tend to browse for shorter periods, likely because they are looking for specific event-related information. Overall, this indicates that the split helped create a more engaged audience on the Recording Academy site but resulted in shorter, more task-focused visits on the Grammys site.
A94: Part 3: Device Breakdown
A96: Ray and his team want to optimize the site for mobile users, but first, they need to determine what percentage of visitors are accessing Grammy.com via mobile devices.
A98: 7a | B98: In the Grammys Data sheet there is a mobile_visits table on the right. Use the XLOOKUP function to fill in the missing column of the grammys table by looking up the corresponding date and returning the mobile_visitors column of the mobile_visits table. If the date is not found, the function should return the numeric value 0. | D98: Hint!
A101: 7b | B101: What percentage of users across all dates in the dataset use a mobile device to visit the website? To calculate this value, you will the total number of mobile_visitors and divide by the total number of visitors | C101: =(SUMIFS(Grammys[mobile_visitors],Grammys[website_content],"Grammys")/SUMIFS(Grammys[visitors],Grammys[website_content],"Grammys")) -> 0.73692175 | D101: Hint!
A103: 7c | B103: Based on your answer, how might a high percentage of mobile visitors affect engagement metrics like bounce rate and time on site? Consider factors such as user experience on mobile devices, page load times, and ease of navigation. Remember, you can continue to use ChatGPT as your Teammate to help!
A106: A high percentage of mobile visitors can increase bounce rate and reduce average time on site if the website is not fully optimized for mobile. Mobile users often have slower load times, smaller screens, and more difficult navigation, which can cause them to leave quickly. However, if the mobile experience is well designed, engagement can improve because mobile users tend to visit more frequently and consume content quickly.
A111: Part 4: Making a Business Recommendation
...

Sheet Grammys Data
A1: date | B1: visitors | C1: pageviews | D1: sessions | E1: bounced_sessions | F1: avg_session_duration_secs | G1: event_type | H1: website_content | I1: mobile_visitors | O1: date | P1: mobile_visitors
A2: 42736 | B2: 9611 | C2: 21407 | D2: 10196 | E2: 6490 | F2: 86 | G2: Regular Day | H2: {=_xlfn.IFS(Grammys[[#This Row],[date]] >= DATE(2022,2,1),"Grammys",TRUE,"Grammys TRA")} -> Grammys TRA | I2: =_xlfn.XLOOKUP(Grammys[[#This Row],[date]],mobile_visits[date],mobile_visits[mobile_visitors],0) -> 0 | O2: 44593 | P2: 23014
A3: 42737 | B3: 10752 | C3: 25658 | D3: 11350 | E3: 7055 | F3: 100 | G3: Regular Day | H3: {=_xlfn.IFS(Grammys[[#This Row],[date]] >= DATE(2022,2,1),"Grammys",TRUE,"Grammys TRA")} -> Grammys TRA | I3: =_xlfn.XLOOKUP(Grammys[[#This Row],[date]],mobile_visits[date],mobile_visits[mobile_visitors],0) -> 0 | O3: 44594 | P3: 19951
A4: 42738 | B4: 11425 | C4: 27062 | D4: 12215 | E4: 7569 | F4: 92 | G4: Regular Day | H4: {=_xlfn.IFS(Grammys[[#This Row],[date]] >= DATE(2022,2,1),"Grammys",TRUE,"Grammys TRA")} -> Grammys TRA | I4: =_xlfn.XLOOKUP(Grammys[[#This Row],[date]],mobile_visits[date],mobile_visits[mobile_visitors],0) -> 0 | O4: 44595 | P4: 21567
A5: 42739 | B5: 13098 | C5: 29189 | D5: 13852 | E5: 8929 | F5: 90 | G5: Regular Day | H5: {=_xlfn.IFS(Grammys[[#This Row],[date]] >= DATE(2022,2,1),"Grammys",TRUE,"Grammys TRA")} -> Grammys TRA | I5: =_xlfn.XLOOKUP(Grammys[[#This Row],[date]],mobile_visits[date],mobile_visits[mobile_visitors],0) -> 0 | K5: event_type | L5: Average of visitors | O5: 44596 | P5: 18362
A6: 42740 | B6: 12234 | C6: 28288 | D6: 12990 | E6: 8105 | F6: 95 | G6: Regular Day | H6: {=_xlfn.IFS(Grammys[[#This Row],[date]] >= DATE(2022,2,1),"Grammys",TRUE,"Grammys TRA")} -> Grammys TRA | I6: =_xlfn.XLOOKUP(Grammys[[#This Row],[date]],mobile_visits[date],mobile_visits[mobile_visitors],0) -> 0 | K6: Grammy Awards | L6: 1389590.2 | O6: 44597 | P6: 12590
A7: 42741 | B7: 11461 | C7: 28022 | D7: 12309 | E7: 7500 | F7: 95 | G7: Regular Day | H7: {=_xlfn.IFS(Grammys[[#This Row],[date]] >= DATE(2022,2,1),"Grammys",TRUE,"Grammys TRA")} -> Grammys TRA | I7: =_xlfn.XLOOKUP(Grammys[[#This Row],[date]],mobile_visits[date],mobile_visits[mobile_visitors],0) -> 0 | K7: Regular Day | L7: 32388.277 | O7: 44598 | P7: 12316
A8: 42742 | B8: 11183 | C8: 27491 | D8: 11993 | E8: 7287 | F8: 94 | G8: Regular Day | H8: {=_xlfn.IFS(Grammys[[#This Row],[date]] >= DATE(2022,2,1),"Grammys",TRUE,"Grammys TRA")} -> Grammys TRA | I8: =_xlfn.XLOOKUP(Grammys[[#This Row],[date]],mobile_visits[date],mobile_visits[mobile_visitors],0) -> 0 | K8: Grand Total | L8: 39921.849 | O8: 44599 | P8: 10416
A9: 42743 | B9: 16265 | C9: 38529 | D9: 17361 | E9: 10587 | F9: 84 | G9: Regular Day | H9: {=_xlfn.IFS(Grammys[[#This Row],[date]] >= DATE(2022,2,1),"Grammys",TRUE,"Grammys TRA")} -> Grammys TRA | I9: =_xlfn.XLOOKUP(Grammys[[#This Row],[date]],mobile_visits[date],mobile_visits[mobile_visitors],0) -> 0 | O9: 44600 | P9: 19299
A10: 42744 | B10: 17852 | C10: 40698 | D10: 18914 | E10: 11697 | F10: 87 | G10: Regular Day | H10: {=_xlfn.IFS(Grammys[[#This Row],[date]] >= DATE(2022,2,1),"Grammys",TRUE,"Grammys TRA")} -> Grammys TRA | I10: =_xlfn.XLOOKUP(Grammys[[#This Row],[date]],mobile_visits[date],mobile_visits[mobile_visitors],0) -> 0 | O10: 44601 | P10: 16050
A11: 42745 | B11: 14211 | C11: 33218 | D11: 15124 | E11: 9270 | F11: 96 | G11: Regular Day | H11: {=_xlfn.IFS(Grammys[[#This Row],[date]] >= DATE(2022,2,1),"Grammys",TRUE,"Grammys TRA")} -> Grammys TRA | I11: =_xlfn.XLOOKUP(Grammys[[#This Row],[date]],mobile_visits[date],mobile_visits[mobile_visitors],0) -> 0 | O11: 44602 | P11: 13590
A12: 42746 | B12: 13456 | C12: 30704 | D12: 14397 | E12: 8922 | F12: 99 | G12: Regular Day | H12: {=_xlfn.IFS(Grammys[[#This Row],[date]] >= DATE(2022,2,1),"Grammys",TRUE,"Grammys TRA")} -> Grammys TRA | I12: =_xlfn.XLOOKUP(Grammys[[#This Row],[date]],mobile_visits[date],mobile_visits[mobile_visitors],0) -> 0 | O12: 44603 | P12: 13393
A13: 42747 | B13: 13616 | C13: 31559 | D13: 14613 | E13: 9227 | F13: 98 | G13: Regular Day | H13: {=_xlfn.IFS(Grammys[[#This Row],[date]] >= DATE(2022,2,1),"Grammys",TRUE,"Grammys TRA")} -> Grammys TRA | I13: =_xlfn.XLOOKUP(Grammys[[#This Row],[date]],mobile_visits[date],mobile_visits[mobile_visitors],0) -> 0 | O13: 44604 | P13: 13824
A14: 42748 | B14: 11880 | C14: 27526 | D14: 12805 | E14: 8148 | F14: 97 | G14: Regular Day | H14: {=_xlfn.IFS(Grammys[[#This Row],[date]] >= DATE(2022,2,1),"Grammys",TRUE,"Grammys TRA")} -> Grammys TRA | I14: =_xlfn.XLOOKUP(Grammys[[#This Row],[date]],mobile_visits[date],mobile_visits[mobile_visitors],0) -> 0 | O14: 44605 | P14: 15704
A15: 42749 | B15: 11888 | C15: 27940 | D15: 12608 | E15: 7804 | F15: 93 | G15: Regular Day | H15: {=_xlfn.IFS(Grammys[[#This Row],[date]] >= DATE(2022,2,1),"Grammys",TRUE,"Grammys TRA")} -> Grammys TRA | I15: =_xlfn.XLOOKUP(Grammys[[#This Row],[date]],mobile_visits[date],mobile_visits[mobile_visitors],0) -> 0 | O15: 44606 | P15: 9362
A16: 42750 | B16: 12706 | C16: 29109 | D16: 13416 | E16: 8349 | F16: 96 | G16: Regular Day | H16: {=_xlfn.IFS(Grammys[[#This Row],[date]] >= DATE(2022,2,1),"Grammys",TRUE,"Grammys TRA")} -> Grammys TRA | I16: =_xlfn.XLOOKUP(Grammys[[#This Row],[date]],mobile_visits[date],mobile_visits[mobile_visitors],0) -> 0 | O16: 44607 | P16: 9596
A17: 42751 | B17: 12691 | C17: 30284 | D17: 13525 | E17: 8282 | F17: 100 | G17: Regular Day | H17: {=_xlfn.IFS(Grammys[[#This Row],[date]] >= DATE(2022,2,1),"Grammys",TRUE,"Grammys TRA")} -> Grammys TRA | I17: =_xlfn.XLOOKUP(Grammys[[#This Row],[date]],mobile_visits[date],mobile_visits[mobile_visitors],0) -> 0 | O17: 44608 | P17: 11132
A18: 42752 | B18: 13260 | C18: 33596 | D18: 14260 | E18: 8514 | F18: 121 | G18: Regular Day | H18: {=_xlfn.IFS(Grammys[[#This Row],[date]] >= DATE(2022,2,1),"Grammys",TRUE,"Grammys TRA")} -> Grammys TRA | I18: =_xlfn.XLOOKUP(Grammys[[#This Row],[date]],mobile_visits[date],mobile_visits[mobile_visitors],0) -> 0 | O18: 44609 | P18: 10821
A19: 42753 | B19: 14483 | C19: 36586 | D19: 15809 | E19: 9494 | F19: 117 | G19: Regular Day | H19: {=_xlfn.IFS(Grammys[[#This Row],[date]] >= DATE(2022,2,1),"Grammys",TRUE,"Grammys TRA")} -> Grammys TRA | I19: =_xlfn.XLOOKUP(Grammys[[#This Row],[date]],mobile_visits[date],mobile_visits[mobile_visitors],0) -> 0 | O19: 44610 | P19: 8344
A20: 42754 | B20: 13551 | C20: 31964 | D20: 14694 | E20: 9118 | F20: 104 | G20: Regular Day | H20: {=_xlfn.IFS(Grammys[[#This Row],[date]] >= DATE(2022,2,1),"Grammys",TRUE,"Grammys TRA")} -> Grammys TRA | I20: =_xlfn.XLOOKUP(Grammys[[#This Row],[date]],mobile_visits[date],mobile_visits[mobile_visitors],0) -> 0 | O20: 44611 | P20: 9054
... A516: 43250 | B516: 14774 | C516: 20555 | D516: 14911 | E516: 7695 | F516: 274 | G516: Regular Day | H516: {=_xlfn.IFS(Grammys[[#This Row],[date]] >= DATE(2022,2,1),"Grammys",TRUE,"Grammys TRA")} -> Grammys TRA | I516: =_xlfn.XLOOKUP(Grammys[[#This Row],[date]],mobile_visits[date],mobile_visits[mobile_visitors],0) -> 0 | O516: 45107 | P516: 14446
A517: 43251 | B517: 13053 | C517: 17758 | D517: 13211 | E517: 6417 | F517: 242 | G517: Regular Day | H517: {=_xlfn.IFS(Grammys[[#This Row],[date]] >= DATE(2022,2,1),"Grammys",TRUE,"Grammys TRA")} -> Grammys TRA | I517: =_xlfn.XLOOKUP(Grammys[[#This Row],[date]],mobile_visits[date],mobile_visits[mobile_visitors],0) -> 0
A518: 43252 | B518: 11825 | C518: 16289 | D518: 11767 | E518: 6072 | F518: 265 | G518: Regular Day | H518: {=_xlfn.IFS(Grammys[[#This Row],[date]] >= DATE(2022,2,1),"Grammys",TRUE,"Grammys TRA")} -> Grammys TRA | I518: =_xlfn.XLOOKUP(Grammys[[#This Row],[date]],mobile_visits[date],mobile_visits[mobile_visitors],0) -> 0
A519: 43253 | B519: 9932 | C519: 13248 | D519: 9881 | E519: 5747 | F519: 213 | G519: Regular Day | H519: {=_xlfn.IFS(Grammys[[#This Row],[date]] >= DATE(2022,2,1),"Grammys",TRUE,"Grammys TRA")} -> Grammys TRA | I519: =_xlfn.XLOOKUP(Grammys[[#This Row],[date]],mobile_visits[date],mobile_visits[mobile_visitors],0) -> 0
A520: 43254 | B520: 9586 | C520: 13226 | D520: 9530 | E520: 5468 | F520: 254 | G520: Regular Day | H520: {=_xlfn.IFS(Grammys[[#This Row],[date]] >= DATE(2022,2,1),"Grammys",TRUE,"Grammys TRA")} -> Grammys TRA | I520: =_xlfn.XLOOKUP(Grammys[[#This Row],[date]],mobile_visits[date],mobile_visits[mobile_visitors],0) -> 0
A521: 43255 | B521: 10093 | C521: 14899 | D521: 10245 | E521: 5846 | F521: 324 | G521: Regular Day | H521: {=_xlfn.IFS(Grammys[[#This Row],[date]] >= DATE(2022,2,1),"Grammys",TRUE,"Grammys TRA")} -> Grammys TRA | I521: =_xlfn.XLOOKUP(Grammys[[#This Row],[date]],mobile_visits[date],mobile_visits[mobile_visitors],0) -> 0
A522: 43256 | B522: 10463 | C522: 14842 | D522: 10405 | E522: 5965 | F522: 279 | G522: Regular Day | H522: {=_xlfn.IFS(Grammys[[#This Row],[date]] >= DATE(2022,2,1),"Grammys",TRUE,"Grammys TRA")} -> Grammys TRA | I522: =_xlfn.XLOOKUP(Grammys[[#This Row],[date]],mobile_visits[date],mobile_visits[mobile_visitors],0) -> 0
A523: 43257 | B523: 11449 | C523: 15810 | D523: 11504 | E523: 6819 | F523: 237 | G523: Regular Day | H523: {=_xlfn.IFS(Grammys[[#This Row],[date]] >= DATE(2022,2,1),"Grammys",TRUE,"Grammys TRA")} -> Grammys TRA | I523: =_xlfn.XLOOKUP(Grammys[[#This Row],[date]],mobile_visits[date],mobile_visits[mobile_visitors],0) -> 0
A524: 43258 | B524: 10669 | C524: 15170 | D524: 10796 | E524: 6249 | F524: 255 | G524: Regular Day | H524: {=_xlfn.IFS(Grammys[[#This Row],[date]] >= DATE(2022,2,1),"Grammys",TRUE,"Grammys TRA")} -> Grammys TRA | I524: =_xlfn.XLOOKUP(Grammys[[#This Row],[date]],mobile_visits[date],mobile_visits[mobile_visitors],0) -> 0
A525: 43259 | B525: 10215 | C525: 14300 | D525: 10250 | E525: 5891 | F525: 267 | G525: Regular Day | H525: {=_xlfn.IFS(Grammys[[#This Row],[date]] >= DATE(2022,2,1),"Grammys",TRUE,"Grammys TRA")} -> Grammys TRA | I525: =_xlfn.XLOOKUP(Grammys[[#This Row],[date]],mobile_visits[date],mobile_visits[mobile_visitors],0) -> 0
A526: 43260 | B526: 21010 | C526: 27986 | D526: 21659 | E526: 8835 | F526: 279 | G526: Regular Day | H526: {=_xlfn.IFS(Grammys[[#This Row],[date]] >= DATE(2022,2,1),"Grammys",TRUE,"Grammys TRA")} -> Grammys TRA | I526: =_xlfn.XLOOKUP(Grammys[[#This Row],[date]],mobile_visits[date],mobile_visits[mobile_visitors],0) -> 0
A527: 43261 | B527: 14918 | C527: 20506 | D527: 15207 | E527: 7698 | F527: 306 | G527: Regular Day | H527: {=_xlfn.IFS(Grammys[[#This Row],[date]] >= DATE(2022,2,1),"Grammys",TRUE,"Grammys TRA")} -> Grammys TRA | I527: =_xlfn.XLOOKUP(Grammys[[#This Row],[date]],mobile_visits[date],mobile_visits[mobile_visitors],0) -> 0
A528: 43262 | B528: 22842 | C528: 30176 | D528: 23244 | E528: 9366 | F528: 264 | G528: Regular Day | H528: {=_xlfn.IFS(Grammys[[#This Row],[date]] >= DATE(2022,2,1),"Grammys",TRUE,"Grammys TRA")} -> Grammys TRA | I528: =_xlfn.XLOOKUP(Grammys[[#This Row],[date]],mobile_visits[date],mobile_visits[mobile_visitors],0) -> 0
... A2343: 45077 | B2343: 31253 | C2343: 85686 | D2343: 33237 | E2343: 8200 | F2343: 106 | G2343: Regular Day | H2343: {=_xlfn.IFS(Grammys[[#This Row],[date]] >= DATE(2022,2,1),"Grammys",TRUE,"Grammys TRA")} -> Grammys | I2343: =_xlfn.XLOOKUP(Grammys[[#This Row],[date]],mobile_visits[date],mobile_visits[mobile_visitors],0) -> 22726

Sheet Recording Academy Data
A1: date | B1: year | C1: visitors | D1: pageviews | E1: sessions | F1: bounced_sessions | G1: avg_session_duration_secs
A2: 44593 | B2: =YEAR(TRA[[#This Row],[date]]) -> 2022 | C2: 928 | D2: 2856 | E2: 1092 | F2: 591 | G2: 148
A3: 44594 | B3: =YEAR(TRA[[#This Row],[date]]) -> 2022 | C3: 1329 | D3: 3233 | E3: 1490 | F3: 923 | G3: 90
A4: 44595 | B4: =YEAR(TRA[[#This Row],[date]]) -> 2022 | C4: 1138 | D4: 3340 | E4: 1322 | F4: 754 | G4: 127
A5: 44596 | B5: =YEAR(TRA[[#This Row],[date]]) -> 2022 | C5: 811 | D5: 2552 | E5: 963 | F5: 534 | G5: 142
A6: 44597 | B6: =YEAR(TRA[[#This Row],[date]]) -> 2022 | C6: 541 | D6: 1530 | E6: 602 | F6: 326 | G6: 111
A7: 44598 | B7: =YEAR(TRA[[#This Row],[date]]) -> 2022 | C7: 536 | D7: 1669 | E7: 610 | F7: 339 | G7: 147
A8: 44599 | B8: =YEAR(TRA[[#This Row],[date]]) -> 2022 | C8: 921 | D8: 3512 | E8: 1117 | F8: 567 | G8: 198
A9: 44600 | B9: =YEAR(TRA[[#This Row],[date]]) -> 2022 | C9: 1106 | D9: 3662 | E9: 1296 | F9: 661 | G9: 163
A10: 44601 | B10: =YEAR(TRA[[#This Row],[date]]) -> 2022 | C10: 1181 | D10: 4209 | E10: 1382 | F10: 725 | G10: 150
A11: 44602 | B11: =YEAR(TRA[[#This Row],[date]]) -> 2022 | C11: 1134 | D11: 3473 | E11: 1341 | F11: 727 | G11: 140
A12: 44603 | B12: =YEAR(TRA[[#This Row],[date]]) -> 2022 | C12: 871 | D12: 3263 | E12: 1045 | F12: 577 | G12: 183
A13: 44604 | B13: =YEAR(TRA[[#This Row],[date]]) -> 2022 | C13: 628 | D13: 1791 | E13: 726 | F13: 418 | G13: 116
... A486: 45077 | B486: =YEAR(TRA[[#This Row],[date]]) -> 2023 | C486: 1618 | D486: 5163 | E486: 2072 | F486: 1195 | G486: 172

Sheet LevelUp
A1: LevelUp | A/B Testing for The Grammys | I1: website version | J1: group | K1: CTA clicked
I2: websites combined | J2: control | K2: 0
A3: As part of your analysis of the website split between Grammy.com and TheRecordingAcademy.com, you're also tasked with conducting a controlled A/B test to assess how the change affects visitor engagement with a key Call-to-Action (CTA) on the homepage. The CTA reads: "Click here to watch highlights from the 64th GRAMMY Awards!" To ensure valid results, a portion of users were randomly assigned to see the old, combined site and a another portion of users were assigned to see one of the new split sites. The control group consists of visitors who were directed to the original, combined Grammy and Recording Academy website. The test group consists of visitors who were directed to either Grammy.com or TheRecordingAcademy.com after the split. For this LevelUp, you'll evaluate the results of this A/B test and determine whether splitting the website into two separeate sites had a significant impact on the likelihood to engage with the CTA button and watch the Grammy highlights. | I3: websites combined | J3: control | K3: 0
I4: websites split | J4: test | K4: 0
I5: websites combined | J5: control | K5: 0
I6: websites combined | J6: control | K6: 0
I7: websites combined | J7: control | K7: 0
I8: websites combined | J8: control | K8: 0
I9: websites split | J9: test | K9: 0
I10: websites combined | J10: control | K10: 0
I11: websites combined | J11: control | K11: 0
I12: websites combined | J12: control | K12: 0
I13: websites split | J13: test | K13: 0
I14: websites split | J14: test | K14: 0
I15: websites split | J15: test | K15: 0
A16: 1 | B16: In a sentence or two, state the null hypothesis for The Academy's A/B test. | D16: ple | I16: websites combined | J16: control | K16: 0
A17: There is no difference in engagement with the CTA between visitors to the original combined website and visitors to the split sites. | I17: websites combined | J17: control | K17: 0
I18: websites split | J18: test | K18: 0
A19: 2 | B19: In a sentence or two, state the alternative hypothesis for The Academy's A/B test. | I19: websites combined | J19: control | K19: 0
A20: Visitors to the split sites (Grammy.com or RecordingAcademy.com) show higher engagement with the CTA compared to visitors to the original combined website. | I20: websites split | J20: test | K20: 0
I21: websites split | J21: test | K21: 0
A22: Data for the A/B Test was collected, and the results can be found in the ABTest data table to the right. In the opened column, 0 indicates that the button was not clicked, while 1 indicates the button was clicked. | I22: websites combined | J22: control | K22: 1
E23: Insert a PivotTable below here! | I23: websites combined | J23: control | K23: 0
A24: 3 | B24: In the sheet called PivotTable, create a PivotTable that summarizes the total visitors in the test and control groups during this test and the number of times the CTA button was clicked in each group. | I24: websites combined | J24: control | K24: 0
I25: websites split | J25: test | K25: 0
A26: 4 | B26: To check your work, what is the difference in the number of visitors between the two groups? | C26: =G29-G28 -> 302 | I26: websites combined | J26: control | K26: 0
F27: group | G27: Count of group | H27: Sum of CTA clicked | I27: websites combined | J27: control | K27: 0
A28: 5 | B28: What is the difference in the number of CTA clicks between the two groups? | C28: =H29-H28 -> 39 | F28: control | G28: 3797 | H28: 119 | I28: websites split | J28: test | K28: 0
F29: test | G29: 4099 | H29: 158 | I29: websites split | J29: test | K29: 0
A30: Use the A/B Test Significance Calculator below to help you answer the following questions. | F30: Grand Total | G30: 7896 | H30: 277 | I30: websites combined | J30: control | K30: 0
A31: =HYPERLINK("https://neilpatel.com/ab-testing-calculator/","A/B Testing Significance Calculator") -> A/B Testing Significance Calculator | I31: websites combined | J31: control | K31: 0
A32: 6 | B32: Which group performed better, the control or the test group? Are your results statistically significant? | I32: websites combined | J32: control | K32: 0
I33: websites combined | J33: control | K33: 0
A34: As per the calculation, the test group performed better by 23%, which creates a 96% of confidence level to implement our test group. Also, the results are significant as well, which gives enough evidence that the Null hypothesis should be rejected. | I34: websites combined | J34: control | K34: 0
I35: websites split | J35: test | K35: 0
I36: websites split | J36: test | K36: 0
I37: websites combined | J37: control | K37: 0
I38: websites combined | J38: control | K38: 0
A39: 7 | B39: Based on these results, should The Recording Academy continue with the split website structure? Explain why Remember you can use ChatGPT as your teammate in helping to interpret these results in the context of your hypothesis and the overall goal of increasing website engagement! | I39: websites combined | J39: control | K39: 0
I40: websites combined | J40: control | K40: 0
...

Sheet Data Dictionary
A1: Data Dictionary: Grammys
A3: column name | B3: description
A4: date | B4: The date of the recorded website activity.
A5: visitors | B5: The number of unique visitors to the website on a given day.
A6: pageviews | B6: The total number of pages viewed by all visitors.
A7: sessions | B7: The total number of browsing sessions initiated by visitors.
A8: bounced_sessions | B8: The number of sessions where the user left the site without interacting.
A9: avg_session_duration_secs | B9: The average length of a session in seconds.
A10: event_type | B10: The type of event occurring on that date (e.g., Grammy Awards, nominee announcements).
A11: website_content | B11: The type of content hosted on the website that day (e.g., "Grammys" or "Grammys + TRA").
A12: mobile_visitors | B12: The number of visitors accessing the website from a mobile device.
A14: Data Dictionary: TRA
A16: column name | B16: description
A17: date | B17: The date of the recorded website activity.
A18: visitors | B18: The number of unique visitors to the website on a given day.
A19: pageviews | B19: The total number of pages viewed by all visitors.
A20: sessions | B20: The total number of browsing sessions initiated by visitors.
A21: bounced_sessions | B21: The number of sessions where the user left the site without interacting.
A22: avg_session_duration_secs | B22: The average length of a session in seconds.
A23: event_type | B23: The type of event occurring on that date (e.g., Grammy Awards, nominee announcements).
A24: website_content | B24: The type of content hosted on the website that day (e.g., "Grammys" or "Grammys + TRA").
A25: mobile_visitors | B25: The number of visitors accessing the website from a mobile device.

Sheet Solutions
A1: Question | B1: Value | C1: Tolerance | D1: student-solution | E1: student-formula
A2: 4a | B2: 2.7792846 | C2: 0.01 | D2: =IFERROR(INDEX('Website Performance Analysis'!$C$68,1,1),"no solution") -> 2.7792846 | E2: =IFERROR(_xlfn.FORMULATEXT(INDEX('Website Performance Analysis'!$C$68,1)),"no formula") -> =(SUM('Recording Academy Data'!D:D)/SUM('Recording Academy Data'!E:E))
A3: 4b | B3: 2.2532667 | C3: 0.01 | D3: =IFERROR(INDEX('Website Performance Analysis'!$C$69,1,1),"no solution") -> 2.2532667 | E3: =IFERROR(_xlfn.FORMULATEXT(INDEX('Website Performance Analysis'!$C$69,1)),"no formula") -> =H63/I63
A4: 4c | B4: 1.8606084 | C4: 0.01 | D4: =IFERROR(INDEX('Website Performance Analysis'!$C$70,1,1),"no solution") -> 1.8606084 | E4: =IFERROR(_xlfn.FORMULATEXT(INDEX('Website Performance Analysis'!$C$70,1)),"no formula") -> =H64/I64
A5: 5a | B5: 0.33671924 | C5: 0.001 | D5: =IFERROR(INDEX('Website Performance Analysis'!$C$79,1,1),"no solution") -> 0.33671924 | E5: =IFERROR(_xlfn.FORMULATEXT(INDEX('Website Performance Analysis'!$C$79,1)),"no formula") -> =(SUM(TRA[bounced_sessions])/SUM('Recording Academy Data'!E:E))
A6: 5b | B6: 0.40158614 | C6: 0.001 | D6: =IFERROR(INDEX('Website Performance Analysis'!$C$81,1,1),"no solution") -> 0.41584428 | E6: =IFERROR(_xlfn.FORMULATEXT(INDEX('Website Performance Analysis'!$C$81,1)),"no formula") -> =(SUMIFS(Grammys[bounced_sessions],Grammys[website_content],"Grammys TRA")/SUMIFS(Grammys[sessions],Grammys[website_content],"Grammys TRA"))
A7: 5c | B7: 0.41584428 | C7: 0.001 | D7: =IFERROR(INDEX('Website Performance Analysis'!#REF!,1,1),"no solution") -> no solution | E7: =IFERROR(_xlfn.FORMULATEXT(INDEX('Website Performance Analysis'!#REF!,1)),"no formula") -> no formula
A8: 6a | B8: 128.50309 | C8: 0.1 | D8: =IFERROR(INDEX('Website Performance Analysis'!$C$85,1,1),"no solution") -> 128.50309 | E8: =IFERROR(_xlfn.FORMULATEXT(INDEX('Website Performance Analysis'!$C$85,1)),"no formula") -> =AVERAGE(TRA[avg_session_duration_secs])
A9: 6b | B9: 82.985567 | C9: 0.1 | D9: =IFERROR(INDEX('Website Performance Analysis'!$C$86,1,1),"no solution") -> 82.985567 | E9: =IFERROR(_xlfn.FORMULATEXT(INDEX('Website Performance Analysis'!$C$86,1)),"no formula") -> =AVERAGEIFS(Grammys[avg_session_duration_secs],Grammys[website_content],"Grammys")
A10: 6c | B10: 102.85353 | C10: 0.1 | D10: =IFERROR(INDEX('Website Performance Analysis'!$C$87,1,1),"no solution") -> 102.85353 | E10: =IFERROR(_xlfn.FORMULATEXT(INDEX('Website Performance Analysis'!$C$87,1)),"no formula") -> =AVERAGEIFS(Grammys[avg_session_duration_secs],Grammys[website_content],"Grammys TRA")
A11: 7b | B11: 0.73692175 | C11: 0.001 | D11: =IFERROR(INDEX('Website Performance Analysis'!$C$101:C$102,1,1),"no solution") -> 0.73692175 | E11: =IFERROR(_xlfn.FORMULATEXT(INDEX('Website Performance Analysis'!$C$101:C$102,1)),"no formula") -> =(SUMIFS(Grammys[mobile_visitors],Grammys[website_content],"Grammys")/SUMIFS(Grammys[visitors],Grammys[website_content],"Grammys"))
A12: LevelUp4 | B12: 302 | C12: 0 | D12: =IFERROR(INDEX(LevelUp!$C$26:C$27,1,1),"no solution") -> 302 | E12: =IFERROR(_xlfn.FORMULATEXT(INDEX(LevelUp!$C$26:C$27,1)),"no formula") -> =G29-G28
A13: LevelUp5 | B13: 39 | C13: 0 | D13: =IFERROR(INDEX(LevelUp!$C$28:C$29,1,1),"no solution") -> 39 | E13: =IFERROR(_xlfn.FORMULATEXT(INDEX(LevelUp!$C$28:C$29,1)),"no formula") -> =H29-H28
A14: 1b | B14: free response | D14: =IF(ISBLANK(INDEX('Website Performance Analysis'!$A$42:$C$45,1,1)), "no solution", IF(ISERROR(INDEX('Website Performance Analysis'!$A$42:$C$45,1,1)), "error in parsing the solution", INDEX('Website Performance Analysis'!$A$42:$C$45,1,1))) -> The chart shows clear annual traffic spikes between 2017 and 2023 that align with major Grammy events. The largest spike each year corresponds to the Grammy Awards ceremony (“Show Night”), which typically occurs between late January and early February, except in 2021 and 2022 when the event was delayed to March and April due to COVID-19. Smaller spikes occurring toward the end of each year are likely associated with nomination announcements and performer reveals. The highest traffic occurs in 2021 with approximately 3.3 million visitors, followed by significant peaks in 2019 and 2023. This indicates that website traffic is highly event-driven and concentrated around key Grammy milestones rather than evenly distributed throughout the year.
A15: 2b | D15: =IF(ISBLANK(INDEX('Website Performance Analysis'!$A$53:$C$55,1,1)), "no solution", IF(ISERROR(INDEX('Website Performance Analysis'!$A$53:$C$55,1,1)), "error in parsing the solution", INDEX('Website Performance Analysis'!$A$53:$C$55,1,1))) -> The table shows a significant increase in the average number of visitors during the award ceremony compared to the regular days. During the award show, the average number of visitors was close to 1.4 million, whereas on regular days it was just around 32000, which is about 2% of the total average visitors during the award show. This does not significantly make differences to the visitors for the award show since it still remains in the figure of 1.25 to 1.4 million. The exact number of additional visitors during the award shows was 1,357,201.95406 on average.
A16: 4d | D16: =IF(ISBLANK(INDEX('Website Performance Analysis'!$A$74:$C$75,1,1)), "no solution", IF(ISERROR(INDEX('Website Performance Analysis'!$A$74:$C$75,1,1)), "error in parsing the solution", INDEX('Website Performance Analysis'!$A$74:$C$75,1,1))) -> The pages per session metric indicates that user engagement is higher on the Recording Academy site than on the Grammys site, suggesting that the website split allowed each audience to access more relevant content, with Recording Academy visitors exploring more pages while Grammys users exhibit shorter, event-driven sessions.
A17: 6d | D17: =IF(ISBLANK(INDEX('Website Performance Analysis'!$A$89:$C$92,1,1)), "no solution", IF(ISERROR(INDEX('Website Performance Analysis'!$A$89:$C$92,1,1)), "error in parsing the solution", INDEX('Website Performance Analysis'!$A$89:$C$92,1,1))) -> After the site split, average time on site increased significantly for the Recording Academy (128.50 seconds) compared to the combined site (102.85 seconds), while the Grammys site decreased to 82.99 seconds. This suggests that users who visit the Recording Academy site are more engaged and spend more time consuming content, whereas Grammys visitors tend to browse for shorter periods, likely because they are looking for specific event-related information. Overall, this indicates that the split helped create a more engaged audience on the Recording Academy site but resulted in shorter, more task-focused visits on the Grammys site.
A18: 7c | D18: =IF(ISBLANK(INDEX('Website Performance Analysis'!$A$106:$C$109,1,1)), "no solution", IF(ISERROR(INDEX('Website Performance Analysis'!$A$106:$C$109,1,1)), "error in parsing the solution", INDEX('Website Performance Analysis'!$A$106:$C$109,1,1))) -> A high percentage of mobile visitors can increase bounce rate and reduce average time on site if the website is not fully optimized for mobile. Mobile users often have slower load times, smaller screens, and more difficult navigation, which can cause them to leave quickly. However, if the mobile experience is well designed, engagement can improve because mobile users tend to visit more frequently and consume content quickly.
A19: 8a | D19: =IF(ISBLANK(INDEX('Website Performance Analysis'!$A$118:$C$122,1,1)), "no solution", IF(ISERROR(INDEX('Website Performance Analysis'!$A$118:$C$122,1,1)), "error in parsing the solution", INDEX('Website Performance Analysis'!$A$118:$C$122,1,1))) -> Write a brief business memo to The Recording Academy evaluating whether the decision to split Grammy.com and RecordingAcademy.com improved user engagement. Use the following metrics: pages per session (Recording Academy: 2.78, Grammys: 2.25, combined before split: 1.86), average time on site (Recording Academy: 128.50 seconds, Grammys: 82.99 seconds, combined before split: 102.85 seconds), and bounce rate trends. Summarize the key insights, compare engagement before and after the split, and explain what the changes suggest about user behavior. Based on this analysis, recommend whether the Academy should keep the sites separate, merge them back together, or pursue an alternative strategy such as improving mobile optimization. Keep the tone professional and concise and focus on actionable business recommendations.
A20: 8b | D20: =IF(ISBLANK(INDEX('Website Performance Analysis'!$A$125:$C$128,1,1)), "no solution", IF(ISERROR(INDEX('Website Performance Analysis'!$A$125:$C$128,1,1)), "error in parsing the solution", INDEX('Website Performance Analysis'!$A$125:$C$128,1,1))) -> ChatGPT did well in accurately identifying that the test group outperformed the control group by 23% and that the results were statistically significant with a 96% confidence level, correctly supporting the recommendation to continue the split website structure. However, it initially lacked business-specific phrasing, context on why the improvement matters for engagement goals, and a polished, executive-ready tone. While the key trends were captured, the memo needed refinement to emphasize strategic implications and make it suitable for a leadership presentation.
A21: 8c | D21: =IF(ISBLANK(INDEX('Website Performance Analysis'!$A$131:$C$139,1,1)), "no solution", IF(ISERROR(INDEX('Website Performance Analysis'!$A$131:$C$139,1,1)), "error in parsing the solution", INDEX('Website Performance Analysis'!$A$131:$C$139,1,1))) -> To: Ray, The Recording Academy From: Prabin Uprety Date: 03/01/2026 Subject: Evaluation of Website Split – User Engagement Overview: Our analysis examined whether splitting Grammy.com and RecordingAcademy.com improved user engagement. The control group maintained the combined site, while the test group experienced the split structure. Key Findings: The test group outperformed the control group by 23% across engagement metrics. Pages per session increased for Recording Academy visitors (2.78) compared to Grammys-only (2.25) and combined site (1.86). Average time on site rose significantly for Recording Academy visitors (128.50 seconds) versus Grammys-only (82.99 seconds) and the pre-split combined site (102.85 seconds). Bounce rates decreased for Recording Academy visitors (33.7%) compared to Grammys (40.2%) and the combined site (41.6%). These trends indicate that the split improved engagement for Recording Academy content while Grammys visitors remain more task-focused and event-driven. Recommendation: It is recommended that The Recording Academy maintain the split website structure. The separation allows each audience to access more relevant content, resulting in stronger engagement on the Recording Academy site. To further optimize results, we suggest improving mobile experience, as 73.7% of visitors access the site via mobile devices, which can impact bounce rate and session duration.
A22: LevelUp1 | D22: =IF(ISBLANK(INDEX(LevelUp!$A$17:$C$18,1,1)), "no solution", IF(ISERROR(INDEX(LevelUp!$A$17:$C$18,1,1)), "error in parsing the solution", INDEX(LevelUp!$A$17:$C$18,1,1))) -> There is no difference in engagement with the CTA between visitors to the original combined website and visitors to the split sites.
A23: LevelUp2 | D23: =IF(ISBLANK(INDEX(LevelUp!$A$20:$C$21,1,1)), "no solution", IF(ISERROR(INDEX(LevelUp!$A$20:$C$21,1,1)), "error in parsing the solution", INDEX(LevelUp!$A$20:$C$21,1,1))) -> Visitors to the split sites (Grammy.com or RecordingAcademy.com) show higher engagement with the CTA compared to visitors to the original combined website.
A24: LevelUp6 | D24: =IF(ISBLANK(INDEX(LevelUp!$A$34:$C$38,1,1)), "no solution", IF(ISERROR(INDEX(LevelUp!$A$34:$C$38,1,1)), "error in parsing the solution", INDEX(LevelUp!$A$34:$C$38,1,1))) -> As per the calculation, the test group performed better by 23%, which creates a 96% of confidence level to implement our test group. Also, the results are significant as well, which gives enough evidence that the Null hypothesis should be rejected.
A25: LevelUp7 | D25: =IF(ISBLANK(INDEX(LevelUp!$A$43:$C$47,1,1)), "no solution", IF(ISERROR(INDEX(LevelUp!$A$43:$C$47,1,1)), "error in parsing the solution", INDEX(LevelUp!$A$43:$C$47,1,1))) -> Yes, based on the result, the Recording Academy should continue with the split website structure because, by the A/B testing, our test group, formed by splitting the sites, performed 23% better than the control group with 96% confidence level. This indicates that the change positively impacts website engagement and supports the goal of improving user interaction.
